<?xml version='1.0'?>
<sdf version = '1.4'>
<model name = "AGV_1">
<static>false</static>
<!--Mass by default is on Kg-->
<self_collide>1</self_collide> 
<link name = 'chassisM'>	
    <self_collide>1</self_collide> 
	<pose>0 0 0 0 0 0 </pose>
	<!-- Anchura del perfil Bosch = 0.05m & Radio de la llanta = 0.4-->
	<!-- Masa de la parte central del chassis-->
	<inertial>
	<mass>50</mass>
	</inertial>
	<collision name = 'collision'>
		<geometry>
			<box>
			<!-- Center chasis box-->
			<!--   L   W   H-->	
			<size> 0.9 0.6 0.05</size>
			</box>
		</geometry>
	</collision>

	<visual name='visual'>
	 <geometry>
	    <box>
	    	<!-- Center chasis box-->
			<!--   L   W   H-->	
	      <size> 0.9 0.6 0.05 </size>
	    </box>
	  </geometry>
	</visual>

	<collision name ='Front_Chassis_Section_Collision'>
		<!-- Front Chassis Front Part -->
		<!-- Front section pose meassured from the center of  chassisM -->
		<!--Mitad del Front_Chassis_Section_Collision + Mitad de chassisM para la posición en Y-->
		<pose> 0.6 0 0 0 0 0 </pose>
		<geometry>
			<box>
			<!-- Front chasis box-->
			<!--   L   W   H-->	
			<size> 0.3 0.3 0.05</size>
			</box>
		</geometry>
	</collision>	

	<visual name ='FC_visual visual'>
		<pose> 0.6 0 0 0 0 0 </pose>
		<geometry>
			<box>
			<!-- Front chasis box-->
			<!--   L   W   H-->	
			<size> 0.3 0.3 0.05</size>
			</box>
		</geometry>
	</visual>

	<collision name ='Rear_Chassis_Section_Collision'>
		<!-- Rear Chassis Front Part -->
		<!-- Rear section pose meassured from the center of  chassisM -->
		<!--Mitad del Rear_Chassis_Section_Collision + Mitad de chassisM para la posición en Y-->
		<pose> -0.6 0 0 0 0 0 </pose>
		<geometry>
			<box>
			<!-- Front chasis box-->
			<!--   L   W   H-->	
			<size> 0.3 0.3 0.05</size>
			</box>
		</geometry>
	</collision>	

	<visual name ='RC_visual'>
		<pose> -0.6 0 0 0 0 0 </pose>
		<geometry>
			<box>
			<!-- Front chasis box-->
			<!--   L   W   H-->	
			<size> 0.3 0.3 0.05</size>
			</box>
		</geometry>
	</visual>
</link>


<link name ='left_front_st'>	
    <self_collide>1</self_collide> 
	<pose>0.6 0.14 0 0 0 0</pose>
	<collision name = 'collision_lfs'>
	<geometry>
	<cylinder>
	<radius>0.01</radius>
	<length>0.1</length>
	</cylinder>
	</geometry>
	</collision>

	<visual name = 'visual'>
	<geometry>
	<cylinder>
	<radius>0.01</radius>
	<length>0.1</length>
	</cylinder>
	</geometry>	
	</visual>
</link>

<joint type='revolute' name='left_front_wheel_st' >
	<pose>0 0 0 0 0 0</pose>
	<child>left_front_st</child>
	<parent>chassisM</parent>
	<axis>
	<xyz>0 0 1</xyz>
	</axis>
</joint>

<link name ='left_front_wheel'>

    <self_collide>1</self_collide> 
	<pose>0.6 0.2 0 1.54 0 0</pose>

	<inertial>
	<mass>7</mass>
	</inertial>

	<collision name = 'collision_lfw'>
	<geometry>
	<cylinder>
	<radius>0.1</radius>
	<length>0.01</length>
	</cylinder>
	</geometry>

	<surface>
      <friction>
        <ode>
          <mu>0.7</mu>
          <mu2>0.7</mu2>
        </ode>
      </friction>
    </surface>
	</collision>

	<pose>0.6 0.2 0 1.54 0 0</pose>
	<visual name = 'visual'>
	<geometry>
	<cylinder>
	<radius>0.1</radius>
	<length>0.01</length>
	</cylinder>
	</geometry>

	<material>
    <ambient>0.1 0.1 0.1 1</ambient>
    <diffuse>0.1 0.1 0.2 1</diffuse>
    <specular>0 0 0 0</specular>
    <emissive>0 0 0 1</emissive>
  	</material>
	</visual>
</link>

<joint type='revolute' name='left_front_wheel_hinge' >
	<pose>0 0 0 0 0 0</pose>
	<child>left_front_wheel</child>
	<parent>left_front_st</parent>
	<axis>
	<xyz>0 0 1</xyz>
	</axis>
</joint>

<!--               RIGHT FRONT                     -->

<link name ='right_front_st'>	
    <self_collide>1</self_collide> 
	<pose>0.6 -0.14 0 0 0 0</pose>
	<collision name = 'collision_rfs'>
	<geometry>
	<cylinder>
	<radius>0.01</radius>
	<length>0.1</length>
	</cylinder>
	</geometry>
	</collision>

	<visual name = 'visual'>
	<geometry>
	<cylinder>
	<radius>0.01</radius>
	<length>0.1</length>
	</cylinder>
	</geometry>
	</visual>
</link>

<joint type='revolute' name='right_front_wheel_st' >
	<pose>0 0 0 0 0 0</pose>
	<child>right_front_st</child>
	<parent>chassisM</parent>
	<axis>
	<xyz>0 0 1</xyz>
	</axis>
</joint>

<link name ='right_front_wheel'>

    <self_collide>1</self_collide> 
	<pose>0.6 -0.2 0 1.54 0 0</pose>

	<inertial>
	<mass>7</mass>
	</inertial>

	<collision name = 'collision_rfw'>
	<geometry>
	<cylinder>
	<radius>0.1</radius>
	<length>0.01</length>
	</cylinder>
	</geometry>

	<surface>
      <friction>
        <ode>
          <mu>0.7</mu>
          <mu2>0.7</mu2>
        </ode>
      </friction>
    </surface>
	</collision>

	<pose>0.6 0.2 0 1.54 0 0</pose>
	<visual name = 'visual'>
	<geometry>
	<cylinder>
	<radius>0.1</radius>
	<length>0.01</length>
	</cylinder>
	</geometry>
	</visual>
</link>

<joint type='revolute' name='right_front_wheel_hinge' >
	<pose>0 0 0 0 0 0</pose>
	<child>right_front_wheel</child>
	<parent>right_front_st</parent>
	<axis>
	<xyz>0 0 1</xyz>
	</axis>
</joint>
<!--               RIGHT REAR                     -->
<link name ='right_rear_wheel'>
    <self_collide>1</self_collide> 
	<pose>-0.6 -0.2 0 1.54 0 0</pose>

	<inertial>
	<mass>7</mass>
	</inertial>

	<collision name = 'collision_rrw'>
	<geometry>
	<cylinder>
	<radius>0.1</radius>
	<length>0.01</length>
	</cylinder>
	</geometry>

	<surface>
      <friction>
        <ode>
          <mu>0.7</mu>
          <mu2>0.7</mu2>
        </ode>
      </friction>
    </surface>
	</collision>

	<pose>-0.6 0.2 0 1.54 0 0</pose>
	<visual name = 'visual'>
	<geometry>
	<cylinder>
	<radius>0.1</radius>
	<length>0.01</length>
	</cylinder>
	</geometry>
	</visual>
</link>

<joint type='revolute' name='right_rear_wheel_hinge' >
	<pose>0 0 0 0 0 0</pose>
	<child>right_rear_wheel</child>
	<parent>chassisM</parent>
	<axis>
	<xyz>0 0 1</xyz>
	</axis>
</joint>
<!--               LEFT REAR                     -->
<link name ='left_rear_wheel'>

    <self_collide>1</self_collide> 
	<pose>-0.6 0.2 0 1.54 0 0</pose>

	<inertial>
	<mass>7</mass>
	</inertial>

	<collision name = 'collision_lfw'>
	<geometry>
	<cylinder>
	<radius>0.1</radius>
	<length>0.01</length>
	</cylinder>
	</geometry>

	<surface>
      <friction>
        <ode>
          <mu>0.7</mu>
          <mu2>0.7</mu2>
        </ode>
      </friction>
    </surface>
	</collision>
		
	<pose>-0.6 0.2 0 1.54 0 0</pose>
	<visual name = 'visual'>
	<geometry>
	<cylinder>
	<radius>0.1</radius>
	<length>0.01</length>
	</cylinder>
	</geometry>
	</visual>
</link>

<joint type='revolute' name='left_rear_wheel_hinge' >
	<pose>0 0 0 0 0 0</pose>
	<child>left_rear_wheel</child>
	<parent>chassisM</parent>
	<axis>
	<xyz>0 0 1</xyz>
	</axis>
</joint>

</model>
</sdf>
